2024-05-10 16:47:59,590 - apscheduler.scheduler - INFO - Scheduler started
2024-05-10 16:48:27,443 - telegram.ext.dispatcher - ERROR - No error handlers are registered, logging exception.
Traceback (most recent call last):
  File "/home/dershtal/.local/lib/python3.10/site-packages/telegram/ext/dispatcher.py", line 555, in process_update
    handler.handle_update(update, self, check, context)
  File "/home/dershtal/.local/lib/python3.10/site-packages/telegram/ext/conversationhandler.py", line 626, in handle_update
    new_state = handler.handle_update(update, dispatcher, check_result, context)
  File "/home/dershtal/.local/lib/python3.10/site-packages/telegram/ext/handler.py", line 198, in handle_update
    return self.callback(update, context)
  File "/home/dershtal/Desktop/devops_bot/bot/bot.py", line 124, in button
    ssh.connect(HOST, port=SSH_PORT, username=USERNAME, password=PASSWORD)
  File "/usr/lib/python3/dist-packages/paramiko/client.py", line 368, in connect
    raise NoValidConnectionsError(errors)
paramiko.ssh_exception.NoValidConnectionsError: [Errno None] Unable to connect to port 22 on 192.168.217.153
2024-05-10 16:48:32,467 - telegram.ext.dispatcher - ERROR - No error handlers are registered, logging exception.
Traceback (most recent call last):
  File "/home/dershtal/.local/lib/python3.10/site-packages/telegram/ext/dispatcher.py", line 555, in process_update
    handler.handle_update(update, self, check, context)
  File "/home/dershtal/.local/lib/python3.10/site-packages/telegram/ext/conversationhandler.py", line 626, in handle_update
    new_state = handler.handle_update(update, dispatcher, check_result, context)
  File "/home/dershtal/.local/lib/python3.10/site-packages/telegram/ext/handler.py", line 198, in handle_update
    return self.callback(update, context)
  File "/home/dershtal/Desktop/devops_bot/bot/bot.py", line 124, in button
    ssh.connect(HOST, port=SSH_PORT, username=USERNAME, password=PASSWORD)
  File "/usr/lib/python3/dist-packages/paramiko/client.py", line 368, in connect
    raise NoValidConnectionsError(errors)
paramiko.ssh_exception.NoValidConnectionsError: [Errno None] Unable to connect to port 22 on 192.168.217.153
2024-05-10 16:48:35,667 - telegram.ext.dispatcher - ERROR - No error handlers are registered, logging exception.
Traceback (most recent call last):
  File "/home/dershtal/.local/lib/python3.10/site-packages/telegram/ext/dispatcher.py", line 555, in process_update
    handler.handle_update(update, self, check, context)
  File "/home/dershtal/.local/lib/python3.10/site-packages/telegram/ext/conversationhandler.py", line 626, in handle_update
    new_state = handler.handle_update(update, dispatcher, check_result, context)
  File "/home/dershtal/.local/lib/python3.10/site-packages/telegram/ext/handler.py", line 198, in handle_update
    return self.callback(update, context)
  File "/home/dershtal/Desktop/devops_bot/bot/bot.py", line 124, in button
    ssh.connect(HOST, port=SSH_PORT, username=USERNAME, password=PASSWORD)
  File "/usr/lib/python3/dist-packages/paramiko/client.py", line 368, in connect
    raise NoValidConnectionsError(errors)
paramiko.ssh_exception.NoValidConnectionsError: [Errno None] Unable to connect to port 22 on 192.168.217.153
2024-05-10 16:50:24,034 - apscheduler.scheduler - INFO - Scheduler started
2024-05-10 16:50:32,205 - paramiko.transport - INFO - Connected (version 2.0, client OpenSSH_9.2p1)
2024-05-10 16:50:32,401 - paramiko.transport - INFO - Authentication (password) successful!
2024-05-10 18:46:01,349 - apscheduler.scheduler - INFO - Scheduler started
2024-05-10 18:46:05,998 - telegram.ext.updater - ERROR - Error while getting Updates: Conflict: terminated by other getUpdates request; make sure that only one bot instance is running
2024-05-10 18:46:05,998 - telegram.ext.dispatcher - ERROR - No error handlers are registered, logging exception.
Traceback (most recent call last):
  File "/home/dershtal/.local/lib/python3.10/site-packages/telegram/ext/updater.py", line 646, in _network_loop_retry
    if not action_cb():
  File "/home/dershtal/.local/lib/python3.10/site-packages/telegram/ext/updater.py", line 597, in polling_action_cb
    updates = self.bot.get_updates(
  File "/home/dershtal/.local/lib/python3.10/site-packages/telegram/ext/extbot.py", line 222, in get_updates
    updates = super().get_updates(
  File "/home/dershtal/.local/lib/python3.10/site-packages/telegram/bot.py", line 130, in decorator
    result = func(*args, **kwargs)
  File "/home/dershtal/.local/lib/python3.10/site-packages/telegram/bot.py", line 2861, in get_updates
    self._post(
  File "/home/dershtal/.local/lib/python3.10/site-packages/telegram/bot.py", line 295, in _post
    return self.request.post(
  File "/home/dershtal/.local/lib/python3.10/site-packages/telegram/utils/request.py", line 356, in post
    result = self._request_wrapper(
  File "/home/dershtal/.local/lib/python3.10/site-packages/telegram/utils/request.py", line 283, in _request_wrapper
    raise Conflict(message)
telegram.error.Conflict: Conflict: terminated by other getUpdates request; make sure that only one bot instance is running
2024-05-10 18:46:11,721 - telegram.ext.updater - ERROR - Error while getting Updates: Conflict: terminated by other getUpdates request; make sure that only one bot instance is running
2024-05-10 18:46:11,721 - telegram.ext.dispatcher - ERROR - No error handlers are registered, logging exception.
Traceback (most recent call last):
  File "/home/dershtal/.local/lib/python3.10/site-packages/telegram/ext/updater.py", line 646, in _network_loop_retry
    if not action_cb():
  File "/home/dershtal/.local/lib/python3.10/site-packages/telegram/ext/updater.py", line 597, in polling_action_cb
    updates = self.bot.get_updates(
  File "/home/dershtal/.local/lib/python3.10/site-packages/telegram/ext/extbot.py", line 222, in get_updates
    updates = super().get_updates(
  File "/home/dershtal/.local/lib/python3.10/site-packages/telegram/bot.py", line 130, in decorator
    result = func(*args, **kwargs)
  File "/home/dershtal/.local/lib/python3.10/site-packages/telegram/bot.py", line 2861, in get_updates
    self._post(
  File "/home/dershtal/.local/lib/python3.10/site-packages/telegram/bot.py", line 295, in _post
    return self.request.post(
  File "/home/dershtal/.local/lib/python3.10/site-packages/telegram/utils/request.py", line 356, in post
    result = self._request_wrapper(
  File "/home/dershtal/.local/lib/python3.10/site-packages/telegram/utils/request.py", line 283, in _request_wrapper
    raise Conflict(message)
telegram.error.Conflict: Conflict: terminated by other getUpdates request; make sure that only one bot instance is running
2024-05-10 18:46:18,829 - telegram.ext.updater - ERROR - Error while getting Updates: Conflict: terminated by other getUpdates request; make sure that only one bot instance is running
2024-05-10 18:46:18,830 - telegram.ext.dispatcher - ERROR - No error handlers are registered, logging exception.
Traceback (most recent call last):
  File "/home/dershtal/.local/lib/python3.10/site-packages/telegram/ext/updater.py", line 646, in _network_loop_retry
    if not action_cb():
  File "/home/dershtal/.local/lib/python3.10/site-packages/telegram/ext/updater.py", line 597, in polling_action_cb
    updates = self.bot.get_updates(
  File "/home/dershtal/.local/lib/python3.10/site-packages/telegram/ext/extbot.py", line 222, in get_updates
    updates = super().get_updates(
  File "/home/dershtal/.local/lib/python3.10/site-packages/telegram/bot.py", line 130, in decorator
    result = func(*args, **kwargs)
  File "/home/dershtal/.local/lib/python3.10/site-packages/telegram/bot.py", line 2861, in get_updates
    self._post(
  File "/home/dershtal/.local/lib/python3.10/site-packages/telegram/bot.py", line 295, in _post
    return self.request.post(
  File "/home/dershtal/.local/lib/python3.10/site-packages/telegram/utils/request.py", line 356, in post
    result = self._request_wrapper(
  File "/home/dershtal/.local/lib/python3.10/site-packages/telegram/utils/request.py", line 283, in _request_wrapper
    raise Conflict(message)
telegram.error.Conflict: Conflict: terminated by other getUpdates request; make sure that only one bot instance is running
2024-05-10 18:46:24,016 - telegram.ext.updater - ERROR - Error while getting Updates: Conflict: terminated by other getUpdates request; make sure that only one bot instance is running
2024-05-10 18:46:24,017 - telegram.ext.dispatcher - ERROR - No error handlers are registered, logging exception.
Traceback (most recent call last):
  File "/home/dershtal/.local/lib/python3.10/site-packages/telegram/ext/updater.py", line 646, in _network_loop_retry
    if not action_cb():
  File "/home/dershtal/.local/lib/python3.10/site-packages/telegram/ext/updater.py", line 597, in polling_action_cb
    updates = self.bot.get_updates(
  File "/home/dershtal/.local/lib/python3.10/site-packages/telegram/ext/extbot.py", line 222, in get_updates
    updates = super().get_updates(
  File "/home/dershtal/.local/lib/python3.10/site-packages/telegram/bot.py", line 130, in decorator
    result = func(*args, **kwargs)
  File "/home/dershtal/.local/lib/python3.10/site-packages/telegram/bot.py", line 2861, in get_updates
    self._post(
  File "/home/dershtal/.local/lib/python3.10/site-packages/telegram/bot.py", line 295, in _post
    return self.request.post(
  File "/home/dershtal/.local/lib/python3.10/site-packages/telegram/utils/request.py", line 356, in post
    result = self._request_wrapper(
  File "/home/dershtal/.local/lib/python3.10/site-packages/telegram/utils/request.py", line 283, in _request_wrapper
    raise Conflict(message)
telegram.error.Conflict: Conflict: terminated by other getUpdates request; make sure that only one bot instance is running
2024-05-10 18:46:29,713 - telegram.ext.updater - ERROR - Error while getting Updates: Conflict: terminated by other getUpdates request; make sure that only one bot instance is running
2024-05-10 18:46:29,713 - telegram.ext.dispatcher - ERROR - No error handlers are registered, logging exception.
Traceback (most recent call last):
  File "/home/dershtal/.local/lib/python3.10/site-packages/telegram/ext/updater.py", line 646, in _network_loop_retry
    if not action_cb():
  File "/home/dershtal/.local/lib/python3.10/site-packages/telegram/ext/updater.py", line 597, in polling_action_cb
    updates = self.bot.get_updates(
  File "/home/dershtal/.local/lib/python3.10/site-packages/telegram/ext/extbot.py", line 222, in get_updates
    updates = super().get_updates(
  File "/home/dershtal/.local/lib/python3.10/site-packages/telegram/bot.py", line 130, in decorator
    result = func(*args, **kwargs)
  File "/home/dershtal/.local/lib/python3.10/site-packages/telegram/bot.py", line 2861, in get_updates
    self._post(
  File "/home/dershtal/.local/lib/python3.10/site-packages/telegram/bot.py", line 295, in _post
    return self.request.post(
  File "/home/dershtal/.local/lib/python3.10/site-packages/telegram/utils/request.py", line 356, in post
    result = self._request_wrapper(
  File "/home/dershtal/.local/lib/python3.10/site-packages/telegram/utils/request.py", line 283, in _request_wrapper
    raise Conflict(message)
telegram.error.Conflict: Conflict: terminated by other getUpdates request; make sure that only one bot instance is running
2024-05-10 18:47:39,696 - apscheduler.scheduler - INFO - Scheduler started
2024-05-10 18:47:44,481 - telegram.ext.updater - ERROR - Error while getting Updates: Conflict: terminated by other getUpdates request; make sure that only one bot instance is running
2024-05-10 18:47:44,481 - telegram.ext.dispatcher - ERROR - No error handlers are registered, logging exception.
Traceback (most recent call last):
  File "/home/dershtal/.local/lib/python3.10/site-packages/telegram/ext/updater.py", line 646, in _network_loop_retry
    if not action_cb():
  File "/home/dershtal/.local/lib/python3.10/site-packages/telegram/ext/updater.py", line 597, in polling_action_cb
    updates = self.bot.get_updates(
  File "/home/dershtal/.local/lib/python3.10/site-packages/telegram/ext/extbot.py", line 222, in get_updates
    updates = super().get_updates(
  File "/home/dershtal/.local/lib/python3.10/site-packages/telegram/bot.py", line 130, in decorator
    result = func(*args, **kwargs)
  File "/home/dershtal/.local/lib/python3.10/site-packages/telegram/bot.py", line 2861, in get_updates
    self._post(
  File "/home/dershtal/.local/lib/python3.10/site-packages/telegram/bot.py", line 295, in _post
    return self.request.post(
  File "/home/dershtal/.local/lib/python3.10/site-packages/telegram/utils/request.py", line 356, in post
    result = self._request_wrapper(
  File "/home/dershtal/.local/lib/python3.10/site-packages/telegram/utils/request.py", line 283, in _request_wrapper
    raise Conflict(message)
telegram.error.Conflict: Conflict: terminated by other getUpdates request; make sure that only one bot instance is running
2024-05-10 18:47:50,201 - telegram.ext.updater - ERROR - Error while getting Updates: Conflict: terminated by other getUpdates request; make sure that only one bot instance is running
2024-05-10 18:47:50,202 - telegram.ext.dispatcher - ERROR - No error handlers are registered, logging exception.
Traceback (most recent call last):
  File "/home/dershtal/.local/lib/python3.10/site-packages/telegram/ext/updater.py", line 646, in _network_loop_retry
    if not action_cb():
  File "/home/dershtal/.local/lib/python3.10/site-packages/telegram/ext/updater.py", line 597, in polling_action_cb
    updates = self.bot.get_updates(
  File "/home/dershtal/.local/lib/python3.10/site-packages/telegram/ext/extbot.py", line 222, in get_updates
    updates = super().get_updates(
  File "/home/dershtal/.local/lib/python3.10/site-packages/telegram/bot.py", line 130, in decorator
    result = func(*args, **kwargs)
  File "/home/dershtal/.local/lib/python3.10/site-packages/telegram/bot.py", line 2861, in get_updates
    self._post(
  File "/home/dershtal/.local/lib/python3.10/site-packages/telegram/bot.py", line 295, in _post
    return self.request.post(
  File "/home/dershtal/.local/lib/python3.10/site-packages/telegram/utils/request.py", line 356, in post
    result = self._request_wrapper(
  File "/home/dershtal/.local/lib/python3.10/site-packages/telegram/utils/request.py", line 283, in _request_wrapper
    raise Conflict(message)
telegram.error.Conflict: Conflict: terminated by other getUpdates request; make sure that only one bot instance is running
2024-05-10 18:47:57,176 - telegram.ext.updater - ERROR - Error while getting Updates: Conflict: terminated by other getUpdates request; make sure that only one bot instance is running
2024-05-10 18:47:57,176 - telegram.ext.dispatcher - ERROR - No error handlers are registered, logging exception.
Traceback (most recent call last):
  File "/home/dershtal/.local/lib/python3.10/site-packages/telegram/ext/updater.py", line 646, in _network_loop_retry
    if not action_cb():
  File "/home/dershtal/.local/lib/python3.10/site-packages/telegram/ext/updater.py", line 597, in polling_action_cb
    updates = self.bot.get_updates(
  File "/home/dershtal/.local/lib/python3.10/site-packages/telegram/ext/extbot.py", line 222, in get_updates
    updates = super().get_updates(
  File "/home/dershtal/.local/lib/python3.10/site-packages/telegram/bot.py", line 130, in decorator
    result = func(*args, **kwargs)
  File "/home/dershtal/.local/lib/python3.10/site-packages/telegram/bot.py", line 2861, in get_updates
    self._post(
  File "/home/dershtal/.local/lib/python3.10/site-packages/telegram/bot.py", line 295, in _post
    return self.request.post(
  File "/home/dershtal/.local/lib/python3.10/site-packages/telegram/utils/request.py", line 356, in post
    result = self._request_wrapper(
  File "/home/dershtal/.local/lib/python3.10/site-packages/telegram/utils/request.py", line 283, in _request_wrapper
    raise Conflict(message)
telegram.error.Conflict: Conflict: terminated by other getUpdates request; make sure that only one bot instance is running
2024-05-10 18:48:02,404 - telegram.ext.updater - ERROR - Error while getting Updates: Conflict: terminated by other getUpdates request; make sure that only one bot instance is running
2024-05-10 18:48:02,405 - telegram.ext.dispatcher - ERROR - No error handlers are registered, logging exception.
Traceback (most recent call last):
  File "/home/dershtal/.local/lib/python3.10/site-packages/telegram/ext/updater.py", line 646, in _network_loop_retry
    if not action_cb():
  File "/home/dershtal/.local/lib/python3.10/site-packages/telegram/ext/updater.py", line 597, in polling_action_cb
    updates = self.bot.get_updates(
  File "/home/dershtal/.local/lib/python3.10/site-packages/telegram/ext/extbot.py", line 222, in get_updates
    updates = super().get_updates(
  File "/home/dershtal/.local/lib/python3.10/site-packages/telegram/bot.py", line 130, in decorator
    result = func(*args, **kwargs)
  File "/home/dershtal/.local/lib/python3.10/site-packages/telegram/bot.py", line 2861, in get_updates
    self._post(
  File "/home/dershtal/.local/lib/python3.10/site-packages/telegram/bot.py", line 295, in _post
    return self.request.post(
  File "/home/dershtal/.local/lib/python3.10/site-packages/telegram/utils/request.py", line 356, in post
    result = self._request_wrapper(
  File "/home/dershtal/.local/lib/python3.10/site-packages/telegram/utils/request.py", line 283, in _request_wrapper
    raise Conflict(message)
telegram.error.Conflict: Conflict: terminated by other getUpdates request; make sure that only one bot instance is running
2024-05-10 18:48:08,171 - telegram.ext.updater - ERROR - Error while getting Updates: Conflict: terminated by other getUpdates request; make sure that only one bot instance is running
2024-05-10 18:48:08,171 - telegram.ext.dispatcher - ERROR - No error handlers are registered, logging exception.
Traceback (most recent call last):
  File "/home/dershtal/.local/lib/python3.10/site-packages/telegram/ext/updater.py", line 646, in _network_loop_retry
    if not action_cb():
  File "/home/dershtal/.local/lib/python3.10/site-packages/telegram/ext/updater.py", line 597, in polling_action_cb
    updates = self.bot.get_updates(
  File "/home/dershtal/.local/lib/python3.10/site-packages/telegram/ext/extbot.py", line 222, in get_updates
    updates = super().get_updates(
  File "/home/dershtal/.local/lib/python3.10/site-packages/telegram/bot.py", line 130, in decorator
    result = func(*args, **kwargs)
  File "/home/dershtal/.local/lib/python3.10/site-packages/telegram/bot.py", line 2861, in get_updates
    self._post(
  File "/home/dershtal/.local/lib/python3.10/site-packages/telegram/bot.py", line 295, in _post
    return self.request.post(
  File "/home/dershtal/.local/lib/python3.10/site-packages/telegram/utils/request.py", line 356, in post
    result = self._request_wrapper(
  File "/home/dershtal/.local/lib/python3.10/site-packages/telegram/utils/request.py", line 283, in _request_wrapper
    raise Conflict(message)
telegram.error.Conflict: Conflict: terminated by other getUpdates request; make sure that only one bot instance is running
2024-05-10 18:48:14,703 - telegram.ext.updater - ERROR - Error while getting Updates: Conflict: terminated by other getUpdates request; make sure that only one bot instance is running
2024-05-10 18:48:14,703 - telegram.ext.dispatcher - ERROR - No error handlers are registered, logging exception.
Traceback (most recent call last):
  File "/home/dershtal/.local/lib/python3.10/site-packages/telegram/ext/updater.py", line 646, in _network_loop_retry
    if not action_cb():
  File "/home/dershtal/.local/lib/python3.10/site-packages/telegram/ext/updater.py", line 597, in polling_action_cb
    updates = self.bot.get_updates(
  File "/home/dershtal/.local/lib/python3.10/site-packages/telegram/ext/extbot.py", line 222, in get_updates
    updates = super().get_updates(
  File "/home/dershtal/.local/lib/python3.10/site-packages/telegram/bot.py", line 130, in decorator
    result = func(*args, **kwargs)
  File "/home/dershtal/.local/lib/python3.10/site-packages/telegram/bot.py", line 2861, in get_updates
    self._post(
  File "/home/dershtal/.local/lib/python3.10/site-packages/telegram/bot.py", line 295, in _post
    return self.request.post(
  File "/home/dershtal/.local/lib/python3.10/site-packages/telegram/utils/request.py", line 356, in post
    result = self._request_wrapper(
  File "/home/dershtal/.local/lib/python3.10/site-packages/telegram/utils/request.py", line 283, in _request_wrapper
    raise Conflict(message)
telegram.error.Conflict: Conflict: terminated by other getUpdates request; make sure that only one bot instance is running
2024-05-10 18:48:20,467 - telegram.ext.updater - ERROR - Error while getting Updates: Conflict: terminated by other getUpdates request; make sure that only one bot instance is running
2024-05-10 18:48:20,467 - telegram.ext.dispatcher - ERROR - No error handlers are registered, logging exception.
Traceback (most recent call last):
  File "/home/dershtal/.local/lib/python3.10/site-packages/telegram/ext/updater.py", line 646, in _network_loop_retry
    if not action_cb():
  File "/home/dershtal/.local/lib/python3.10/site-packages/telegram/ext/updater.py", line 597, in polling_action_cb
    updates = self.bot.get_updates(
  File "/home/dershtal/.local/lib/python3.10/site-packages/telegram/ext/extbot.py", line 222, in get_updates
    updates = super().get_updates(
  File "/home/dershtal/.local/lib/python3.10/site-packages/telegram/bot.py", line 130, in decorator
    result = func(*args, **kwargs)
  File "/home/dershtal/.local/lib/python3.10/site-packages/telegram/bot.py", line 2861, in get_updates
    self._post(
  File "/home/dershtal/.local/lib/python3.10/site-packages/telegram/bot.py", line 295, in _post
    return self.request.post(
  File "/home/dershtal/.local/lib/python3.10/site-packages/telegram/utils/request.py", line 356, in post
    result = self._request_wrapper(
  File "/home/dershtal/.local/lib/python3.10/site-packages/telegram/utils/request.py", line 283, in _request_wrapper
    raise Conflict(message)
telegram.error.Conflict: Conflict: terminated by other getUpdates request; make sure that only one bot instance is running
2024-05-10 18:48:26,219 - telegram.ext.updater - ERROR - Error while getting Updates: Conflict: terminated by other getUpdates request; make sure that only one bot instance is running
2024-05-10 18:48:26,219 - telegram.ext.dispatcher - ERROR - No error handlers are registered, logging exception.
Traceback (most recent call last):
  File "/home/dershtal/.local/lib/python3.10/site-packages/telegram/ext/updater.py", line 646, in _network_loop_retry
    if not action_cb():
  File "/home/dershtal/.local/lib/python3.10/site-packages/telegram/ext/updater.py", line 597, in polling_action_cb
    updates = self.bot.get_updates(
  File "/home/dershtal/.local/lib/python3.10/site-packages/telegram/ext/extbot.py", line 222, in get_updates
    updates = super().get_updates(
  File "/home/dershtal/.local/lib/python3.10/site-packages/telegram/bot.py", line 130, in decorator
    result = func(*args, **kwargs)
  File "/home/dershtal/.local/lib/python3.10/site-packages/telegram/bot.py", line 2861, in get_updates
    self._post(
  File "/home/dershtal/.local/lib/python3.10/site-packages/telegram/bot.py", line 295, in _post
    return self.request.post(
  File "/home/dershtal/.local/lib/python3.10/site-packages/telegram/utils/request.py", line 356, in post
    result = self._request_wrapper(
  File "/home/dershtal/.local/lib/python3.10/site-packages/telegram/utils/request.py", line 283, in _request_wrapper
    raise Conflict(message)
telegram.error.Conflict: Conflict: terminated by other getUpdates request; make sure that only one bot instance is running
2024-05-10 18:48:33,203 - telegram.ext.updater - ERROR - Error while getting Updates: Conflict: terminated by other getUpdates request; make sure that only one bot instance is running
2024-05-10 18:48:33,203 - telegram.ext.dispatcher - ERROR - No error handlers are registered, logging exception.
Traceback (most recent call last):
  File "/home/dershtal/.local/lib/python3.10/site-packages/telegram/ext/updater.py", line 646, in _network_loop_retry
    if not action_cb():
  File "/home/dershtal/.local/lib/python3.10/site-packages/telegram/ext/updater.py", line 597, in polling_action_cb
    updates = self.bot.get_updates(
  File "/home/dershtal/.local/lib/python3.10/site-packages/telegram/ext/extbot.py", line 222, in get_updates
    updates = super().get_updates(
  File "/home/dershtal/.local/lib/python3.10/site-packages/telegram/bot.py", line 130, in decorator
    result = func(*args, **kwargs)
  File "/home/dershtal/.local/lib/python3.10/site-packages/telegram/bot.py", line 2861, in get_updates
    self._post(
  File "/home/dershtal/.local/lib/python3.10/site-packages/telegram/bot.py", line 295, in _post
    return self.request.post(
  File "/home/dershtal/.local/lib/python3.10/site-packages/telegram/utils/request.py", line 356, in post
    result = self._request_wrapper(
  File "/home/dershtal/.local/lib/python3.10/site-packages/telegram/utils/request.py", line 283, in _request_wrapper
    raise Conflict(message)
telegram.error.Conflict: Conflict: terminated by other getUpdates request; make sure that only one bot instance is running
2024-05-10 18:49:36,455 - apscheduler.scheduler - INFO - Scheduler started
2024-05-10 20:06:38,223 - apscheduler.scheduler - INFO - Scheduler started
2024-05-10 20:11:38,047 - apscheduler.scheduler - INFO - Scheduler started
2024-05-10 21:10:29,166 - apscheduler.scheduler - INFO - Scheduler started
2024-05-10 21:40:57,978 - apscheduler.scheduler - INFO - Scheduler started
2024-05-10 21:43:20,943 - apscheduler.scheduler - INFO - Scheduler started
2024-05-10 21:44:43,605 - telegram.ext.dispatcher - ERROR - No error handlers are registered, logging exception.
Traceback (most recent call last):
  File "/home/dershtal/.local/lib/python3.10/site-packages/telegram/ext/dispatcher.py", line 555, in process_update
    handler.handle_update(update, self, check, context)
  File "/home/dershtal/.local/lib/python3.10/site-packages/telegram/ext/handler.py", line 198, in handle_update
    return self.callback(update, context)
  File "/home/dershtal/Desktop/devops_bot/bot/bot.py", line 277, in get_repl_logs
    logs = execute_ssh_command("cat /var/log/postgresql/postgresql-15-main.log | head -10")
TypeError: execute_ssh_command() missing 2 required positional arguments: 'command' and 'message_prefix'
2024-05-10 21:45:07,800 - paramiko.transport - INFO - Connected (version 2.0, client OpenSSH_9.2p1)
2024-05-10 21:45:07,929 - paramiko.transport - INFO - Authentication (password) successful!
2024-05-10 21:51:10,991 - apscheduler.scheduler - INFO - Scheduler started
2024-05-10 21:56:52,832 - apscheduler.scheduler - INFO - Scheduler started
2024-05-10 21:57:04,389 - telegram.ext.dispatcher - ERROR - No error handlers are registered, logging exception.
Traceback (most recent call last):
  File "/home/dershtal/.local/lib/python3.10/site-packages/telegram/ext/dispatcher.py", line 555, in process_update
    handler.handle_update(update, self, check, context)
  File "/home/dershtal/.local/lib/python3.10/site-packages/telegram/ext/handler.py", line 198, in handle_update
    return self.callback(update, context)
  File "/home/dershtal/Desktop/devops_bot/bot/bot.py", line 277, in get_repl_logs
    logs = execute_ssh_command("cat /var/log/postgresql/postgresql-15-main.log | head -10")
TypeError: execute_ssh_command() missing 2 required positional arguments: 'command' and 'message_prefix'
2024-05-10 21:59:15,680 - apscheduler.scheduler - INFO - Scheduler started
2024-05-10 21:59:19,870 - paramiko.transport - INFO - Connected (version 2.0, client OpenSSH_9.2p1)
2024-05-10 21:59:20,001 - paramiko.transport - INFO - Authentication (password) successful!
2024-05-10 22:14:17,341 - apscheduler.scheduler - INFO - Scheduler started
2024-05-10 22:23:56,171 - apscheduler.scheduler - INFO - Scheduler started
2024-05-10 22:37:38,082 - apscheduler.scheduler - INFO - Scheduler started
2024-05-10 22:39:57,013 - paramiko.transport - INFO - Connected (version 2.0, client OpenSSH_9.2p1)
2024-05-10 22:39:57,145 - paramiko.transport - INFO - Authentication (password) successful!
2024-05-10 22:40:00,552 - paramiko.transport - INFO - Connected (version 2.0, client OpenSSH_9.2p1)
2024-05-10 22:40:00,681 - paramiko.transport - INFO - Authentication (password) successful!
2024-05-10 22:40:05,812 - paramiko.transport - INFO - Connected (version 2.0, client OpenSSH_9.2p1)
2024-05-10 22:40:05,941 - paramiko.transport - INFO - Authentication (password) successful!
2024-05-10 22:40:17,869 - paramiko.transport - INFO - Connected (version 2.0, client OpenSSH_9.2p1)
2024-05-10 22:40:17,997 - paramiko.transport - INFO - Authentication (password) successful!
2024-05-10 22:40:52,114 - paramiko.transport - INFO - Connected (version 2.0, client OpenSSH_9.2p1)
2024-05-10 22:40:52,249 - paramiko.transport - INFO - Authentication (password) successful!
2024-05-10 22:44:29,375 - paramiko.transport - INFO - Connected (version 2.0, client OpenSSH_9.2p1)
2024-05-10 22:44:29,505 - paramiko.transport - INFO - Authentication (password) successful!
2024-05-10 22:44:41,754 - paramiko.transport - INFO - Connected (version 2.0, client OpenSSH_9.2p1)
2024-05-10 22:44:41,884 - paramiko.transport - INFO - Authentication (password) successful!
2024-05-10 23:03:20,382 - telegram.ext.dispatcher - ERROR - No error handlers are registered, logging exception.
Traceback (most recent call last):
  File "/home/dershtal/.local/lib/python3.10/site-packages/telegram/ext/dispatcher.py", line 555, in process_update
    handler.handle_update(update, self, check, context)
  File "/home/dershtal/.local/lib/python3.10/site-packages/telegram/ext/conversationhandler.py", line 626, in handle_update
    new_state = handler.handle_update(update, dispatcher, check_result, context)
  File "/home/dershtal/.local/lib/python3.10/site-packages/telegram/ext/handler.py", line 198, in handle_update
    return self.callback(update, context)
  File "/home/dershtal/Desktop/devops_bot/bot/bot.py", line 141, in confirm_savepn
    email_address = context.user_data['email_address']
KeyError: 'email_address'
2024-05-10 23:03:25,178 - telegram.ext.dispatcher - ERROR - No error handlers are registered, logging exception.
Traceback (most recent call last):
  File "/home/dershtal/.local/lib/python3.10/site-packages/telegram/ext/dispatcher.py", line 555, in process_update
    handler.handle_update(update, self, check, context)
  File "/home/dershtal/.local/lib/python3.10/site-packages/telegram/ext/conversationhandler.py", line 626, in handle_update
    new_state = handler.handle_update(update, dispatcher, check_result, context)
  File "/home/dershtal/.local/lib/python3.10/site-packages/telegram/ext/handler.py", line 198, in handle_update
    return self.callback(update, context)
  File "/home/dershtal/Desktop/devops_bot/bot/bot.py", line 141, in confirm_savepn
    email_address = context.user_data['email_address']
KeyError: 'email_address'
2024-05-10 23:04:25,972 - paramiko.transport - INFO - Connected (version 2.0, client OpenSSH_9.2p1)
2024-05-10 23:04:26,101 - paramiko.transport - INFO - Authentication (password) successful!
2024-05-10 23:04:32,898 - paramiko.transport - INFO - Connected (version 2.0, client OpenSSH_9.2p1)
2024-05-10 23:04:33,028 - paramiko.transport - INFO - Authentication (password) successful!
2024-05-10 23:04:41,162 - paramiko.transport - INFO - Connected (version 2.0, client OpenSSH_9.2p1)
2024-05-10 23:04:41,292 - paramiko.transport - INFO - Authentication (password) successful!
2024-05-10 23:16:54,406 - paramiko.transport - INFO - Connected (version 2.0, client OpenSSH_9.2p1)
2024-05-10 23:16:54,572 - paramiko.transport - INFO - Authentication (password) successful!
2024-05-10 23:16:56,100 - paramiko.transport - INFO - Connected (version 2.0, client OpenSSH_9.2p1)
2024-05-10 23:16:56,231 - paramiko.transport - INFO - Authentication (password) successful!
2024-05-10 23:17:01,118 - paramiko.transport - INFO - Connected (version 2.0, client OpenSSH_9.2p1)
2024-05-10 23:17:01,247 - paramiko.transport - INFO - Authentication (password) successful!
2024-05-10 23:39:37,337 - apscheduler.scheduler - INFO - Scheduler started
2024-05-10 23:46:08,366 - telegram.ext.dispatcher - ERROR - No error handlers are registered, logging exception.
Traceback (most recent call last):
  File "/home/dershtal/.local/lib/python3.10/site-packages/telegram/ext/dispatcher.py", line 555, in process_update
    handler.handle_update(update, self, check, context)
  File "/home/dershtal/.local/lib/python3.10/site-packages/telegram/ext/conversationhandler.py", line 626, in handle_update
    new_state = handler.handle_update(update, dispatcher, check_result, context)
  File "/home/dershtal/.local/lib/python3.10/site-packages/telegram/ext/handler.py", line 198, in handle_update
    return self.callback(update, context)
  File "/home/dershtal/Desktop/devops_bot/bot/bot.py", line 141, in confirm_savepn
    email_address = context.user_data['email_address']
KeyError: 'email_address'
2024-05-10 23:46:13,343 - telegram.ext.dispatcher - ERROR - No error handlers are registered, logging exception.
Traceback (most recent call last):
  File "/home/dershtal/.local/lib/python3.10/site-packages/telegram/ext/dispatcher.py", line 555, in process_update
    handler.handle_update(update, self, check, context)
  File "/home/dershtal/.local/lib/python3.10/site-packages/telegram/ext/conversationhandler.py", line 626, in handle_update
    new_state = handler.handle_update(update, dispatcher, check_result, context)
  File "/home/dershtal/.local/lib/python3.10/site-packages/telegram/ext/handler.py", line 198, in handle_update
    return self.callback(update, context)
  File "/home/dershtal/Desktop/devops_bot/bot/bot.py", line 141, in confirm_savepn
    email_address = context.user_data['email_address']
KeyError: 'email_address'
2024-05-10 23:46:32,523 - apscheduler.scheduler - INFO - Scheduler started
2024-05-10 23:46:58,621 - telegram.ext.dispatcher - ERROR - No error handlers are registered, logging exception.
Traceback (most recent call last):
  File "/home/dershtal/.local/lib/python3.10/site-packages/telegram/ext/dispatcher.py", line 555, in process_update
    handler.handle_update(update, self, check, context)
  File "/home/dershtal/.local/lib/python3.10/site-packages/telegram/ext/conversationhandler.py", line 626, in handle_update
    new_state = handler.handle_update(update, dispatcher, check_result, context)
  File "/home/dershtal/.local/lib/python3.10/site-packages/telegram/ext/handler.py", line 198, in handle_update
    return self.callback(update, context)
  File "/home/dershtal/Desktop/devops_bot/bot/bot.py", line 141, in confirm_savepn
    email_address = context.user_data['email_address']
KeyError: 'email_address'
2024-05-10 23:46:59,936 - telegram.ext.dispatcher - ERROR - No error handlers are registered, logging exception.
Traceback (most recent call last):
  File "/home/dershtal/.local/lib/python3.10/site-packages/telegram/ext/dispatcher.py", line 555, in process_update
    handler.handle_update(update, self, check, context)
  File "/home/dershtal/.local/lib/python3.10/site-packages/telegram/ext/conversationhandler.py", line 626, in handle_update
    new_state = handler.handle_update(update, dispatcher, check_result, context)
  File "/home/dershtal/.local/lib/python3.10/site-packages/telegram/ext/handler.py", line 198, in handle_update
    return self.callback(update, context)
  File "/home/dershtal/Desktop/devops_bot/bot/bot.py", line 141, in confirm_savepn
    email_address = context.user_data['email_address']
KeyError: 'email_address'
2024-05-10 23:47:00,244 - telegram.ext.dispatcher - ERROR - No error handlers are registered, logging exception.
Traceback (most recent call last):
  File "/home/dershtal/.local/lib/python3.10/site-packages/telegram/ext/dispatcher.py", line 555, in process_update
    handler.handle_update(update, self, check, context)
  File "/home/dershtal/.local/lib/python3.10/site-packages/telegram/ext/conversationhandler.py", line 626, in handle_update
    new_state = handler.handle_update(update, dispatcher, check_result, context)
  File "/home/dershtal/.local/lib/python3.10/site-packages/telegram/ext/handler.py", line 198, in handle_update
    return self.callback(update, context)
  File "/home/dershtal/Desktop/devops_bot/bot/bot.py", line 141, in confirm_savepn
    email_address = context.user_data['email_address']
KeyError: 'email_address'
2024-05-10 23:47:00,578 - telegram.ext.dispatcher - ERROR - No error handlers are registered, logging exception.
Traceback (most recent call last):
  File "/home/dershtal/.local/lib/python3.10/site-packages/telegram/ext/dispatcher.py", line 555, in process_update
    handler.handle_update(update, self, check, context)
  File "/home/dershtal/.local/lib/python3.10/site-packages/telegram/ext/conversationhandler.py", line 626, in handle_update
    new_state = handler.handle_update(update, dispatcher, check_result, context)
  File "/home/dershtal/.local/lib/python3.10/site-packages/telegram/ext/handler.py", line 198, in handle_update
    return self.callback(update, context)
  File "/home/dershtal/Desktop/devops_bot/bot/bot.py", line 141, in confirm_savepn
    email_address = context.user_data['email_address']
KeyError: 'email_address'
2024-05-10 23:47:59,350 - apscheduler.scheduler - INFO - Scheduler started
2024-05-10 23:48:41,567 - telegram.ext.dispatcher - ERROR - No error handlers are registered, logging exception.
Traceback (most recent call last):
  File "/home/dershtal/.local/lib/python3.10/site-packages/telegram/ext/dispatcher.py", line 555, in process_update
    handler.handle_update(update, self, check, context)
  File "/home/dershtal/.local/lib/python3.10/site-packages/telegram/ext/conversationhandler.py", line 626, in handle_update
    new_state = handler.handle_update(update, dispatcher, check_result, context)
  File "/home/dershtal/.local/lib/python3.10/site-packages/telegram/ext/handler.py", line 198, in handle_update
    return self.callback(update, context)
  File "/home/dershtal/Desktop/devops_bot/bot/bot.py", line 141, in confirm_savepn
    email_address = context.user_data['email_address']
KeyError: 'email_address'
2024-05-10 23:49:18,871 - paramiko.transport - INFO - Connected (version 2.0, client OpenSSH_9.2p1)
2024-05-10 23:49:19,001 - paramiko.transport - INFO - Authentication (password) successful!
2024-05-10 23:52:38,025 - apscheduler.scheduler - INFO - Scheduler started
2024-05-10 23:59:26,820 - paramiko.transport - INFO - Connected (version 2.0, client OpenSSH_9.2p1)
2024-05-10 23:59:26,962 - paramiko.transport - INFO - Authentication (password) successful!
2024-05-11 01:14:20,970 - apscheduler.scheduler - INFO - Scheduler started
2024-05-11 01:14:26,705 - paramiko.transport - INFO - Connected (version 2.0, client OpenSSH_9.2p1)
2024-05-11 01:14:26,875 - paramiko.transport - INFO - Authentication (password) successful!
2024-05-11 10:01:39,649 - apscheduler.scheduler - INFO - Scheduler started
